Workbook

Sheet Активисты
A1: ФИО | B1: Имя ККР | C1: Номер группы | D1: Место жительства | E1: Блоки | F1: Телефон | G1: ВК | H1: Telegram | I1: Почта | J1: Форма обучения
A2: Авагян Армен Каренович | B2: =LEFT(A2,FIND(CHAR(160),SUBSTITUTE(A2," ",CHAR(160),2)) - 1) -> Авагян Армен | C2: 324 | D2: Метро Озерная | E2: {=IF(ISERROR(MATCH(1,INDEX(('Списки блоков'!$B$2:$B986=B2)*(ROW('Списки блоков'!$B$2:$B986)<>ROW('Списки блоков'!$B$3)),0),0)),"","БДНС,") &IF(ISERROR(MATCH(1,INDEX(('Списки блоков'!$C$2:$C986=B2)*(ROW('Списки блоков'!$C$2:$C986)<>ROW('Списки блоков'!$C$3)),0),0)),"","Видеолаба,") &IF(ISERROR(MATCH(1,INDEX(('Списки блоков'!$D$2:$D986=B2)*(ROW('Списки блоков'!$D$2:$D986)<>ROW('Списки блоков'!$D$3)),0),0)),"","Декораторы,") &IF(ISERROR(MATCH(1,INDEX(('Списки блоков'!$E$2:$E986=B2)*(ROW('Списки блоков'!$E$2:$E986)<>ROW('Списки блоков'!$E$3)),0),0)),"","Дизайн,") &IF(ISERROR(MATCH(1,INDEX(('Списки блоков'!$F$2:$F986=B2)*(ROW('Списки блоков'!$F$2:$F986)<>ROW('Списки блоков'!$F$3)),0),0)),"","Досуг,") &IF(ISERROR(MATCH(1,INDEX(('Списки блоков'!$G$2:$G986=B2)*(ROW('Списки блоков'!$G$2:$G986)<>ROW('Списки блоков'!$G$3)),0),0)),"","Закупки,") &IF(ISERROR(MATCH(1,INDEX(('Списки блоков'!$H$2:$H986=B2)*(ROW('Списки блоков'!$H$2:$H986)<>ROW('Списки блоков'!$H$3)),0),0)),"","ИнфоБлок,") &IF(ISERROR(MATCH(1,INDEX(('Списки блоков'!$I$2:$I986=B2)*(ROW('Списки блоков'!$I$2:$I986)<>ROW('Списки блоков'!$I$3)),0),0)),"","КГ,") &IF(ISERROR(MATCH(1,INDEX(('Списки блоков'!$J$2:$J986=B2)*(ROW('Списки блоков'!$J$2:$J986)<>ROW('Списки блоков'!$J$3)),0),0)),"","МП,") &IF(ISERROR(MATCH(1,INDEX(('Списки блоков'!$K$2:$K986=B2)*(ROW('Списки блоков'!$K$2:$K986)<>ROW('Списки блоков'!$K$3)),0),0)),"","Профорги,") &IF(ISERROR(MATCH(1,INDEX(('Списки блоков'!$L$2:$L986=B2)*(ROW('Списки блоков'!$L$2:$L986)<>ROW('Списки блоков'!$L$3)),0),0)),"","Спонсоры,") &IF(ISERROR(MATCH(1,INDEX(('Списки блоков'!$M$2:$M986=B2)*(ROW('Списки блоков'!$M$2:$M986)<>ROW('Списки блоков'!$M$3)),0),0)),"","Склад,") &IF(ISERROR(MATCH(1,INDEX(('Списки блоков'!$N$2:$N986=B2)*(ROW('Списки блоков'!$N$2:$N986)<>ROW('Списки блоков'!$N$3)),0),0)),"","Сценаристы,") &IF(ISERROR(MATCH(1,INDEX(('Списки блоков'!$O$2:$O986=B2)*(ROW('Списки блоков'!$O$2:$O986)<>ROW('Списки блоков'!$O$3)),0),0)),"","Техники,") &IF(ISERROR(MATCH(1,INDEX(('Списки блоков'!$P$2:$P986=B2)*(ROW('Списки блоков'!$P$2:$P986)<>ROW('Списки блоков'!$P$3)),0),0)),"","УРС,") &IF(ISERROR(MATCH(1,INDEX(('Списки блоков'!$Q$2:$Q986=B2)*(ROW('Списки блоков'!$Q$2:$Q986)<>ROW('Списки блоков'!$Q$3)),0),0)),"","Фото,") &IF(ISERROR(MATCH(1,INDEX((#REF!=B2)*(ROW(#REF!)<>ROW(#REF!)),0),0)),"","ЭкоБлок,") &IF(ISERROR(MATCH(1,INDEX(('Списки блоков'!$R$2:$R986=B2)*(ROW('Списки блоков'!$R$2:$R986)<>ROW('Списки блоков'!$R$3)),0),0)),"","HR,") &IF(ISERROR(MATCH(1,INDEX(('Списки блоков'!$S$2:$S986=B2)*(ROW('Списки блоков'!$S$2:$S986)<>ROW('Списки блоков'!$S$3)),0),0)),"","Instagram,") &IF(ISERROR(MATCH(1,INDEX(('Списки блоков'!$T$2:$T986=B2)*(ROW('Списки блоков'!$T$2:$T986)<>ROW('Списки блоков'!$T$3)),0),0)),"","Zachёt,") &IF(ISERROR(MATCH(1,INDEX(('Списки блоков'!$U$2:$U986=B2)*(ROW('Списки блоков'!$U$2:$U986)<>ROW('Списки блоков'!$U$3)),0),0)),"","IT,") &IF(ISERROR(MATCH(1,INDEX(('Списки блоков'!$V$2:$V986=B2)*(ROW('Списки блоков'!$V$2:$V986)<>ROW('Списки блоков'!$V$3)),0),0)),"","ДК,")} -> Склад,Техники,Фото, | F2: 89688288304 | G2: https://vk.com/aksel2 | H2: t.me/aksel2 | I2: armen0162@gmail.com | J2: Контракт
A3: Алексеева Алена Алексеевна | B3: Алексеева Алена(old) | C3: 318 | D3: м. Шипиловская | E3: {=IF(ISERROR(MATCH(1,INDEX(('Списки блоков'!$B$2:$B986=B3)*(ROW('Списки блоков'!$B$2:$B986)<>ROW('Списки блоков'!$B$3)),0),0)),"","БДНС,") &IF(ISERROR(MATCH(1,INDEX(('Списки блоков'!$C$2:$C986=B3)*(ROW('Списки блоков'!$C$2:$C986)<>ROW('Списки блоков'!$C$3)),0),0)),"","Видеолаба,") &IF(ISERROR(MATCH(1,INDEX(('Списки блоков'!$D$2:$D986=B3)*(ROW('Списки блоков'!$D$2:$D986)<>ROW('Списки блоков'!$D$3)),0),0)),"","Декораторы,") &IF(ISERROR(MATCH(1,INDEX(('Списки блоков'!$E$2:$E986=B3)*(ROW('Списки блоков'!$E$2:$E986)<>ROW('Списки блоков'!$E$3)),0),0)),"","Дизайн,") &IF(ISERROR(MATCH(1,INDEX(('Списки блоков'!$F$2:$F986=B3)*(ROW('Списки блоков'!$F$2:$F986)<>ROW('Списки блоков'!$F$3)),0),0)),"","Досуг,") &IF(ISERROR(MATCH(1,INDEX(('Списки блоков'!$G$2:$G986=B3)*(ROW('Списки блоков'!$G$2:$G986)<>ROW('Списки блоков'!$G$3)),0),0)),"","Закупки,") &IF(ISERROR(MATCH(1,INDEX(('Списки блоков'!$H$2:$H986=B3)*(ROW('Списки блоков'!$H$2:$H986)<>ROW('Списки блоков'!$H$3)),0),0)),"","ИнфоБлок,") &IF(ISERROR(MATCH(1,INDEX(('Списки блоков'!$I$2:$I986=B3)*(ROW('Списки блоков'!$I$2:$I986)<>ROW('Списки блоков'!$I$3)),0),0)),"","КГ,") &IF(ISERROR(MATCH(1,INDEX(('Списки блоков'!$J$2:$J986=B3)*(ROW('Списки блоков'!$J$2:$J986)<>ROW('Списки блоков'!$J$3)),0),0)),"","МП,") &IF(ISERROR(MATCH(1,INDEX(('Списки блоков'!$K$2:$K986=B3)*(ROW('Списки блоков'!$K$2:$K986)<>ROW('Списки блоков'!$K$3)),0),0)),"","Профорги,") &IF(ISERROR(MATCH(1,INDEX(('Списки блоков'!$L$2:$L986=B3)*(ROW('Списки блоков'!$L$2:$L986)<>ROW('Списки блоков'!$L$3)),0),0)),"","Спонсоры,") &IF(ISERROR(MATCH(1,INDEX(('Списки блоков'!$M$2:$M986=B3)*(ROW('Списки блоков'!$M$2:$M986)<>ROW('Списки блоков'!$M$3)),0),0)),"","Склад,") &IF(ISERROR(MATCH(1,INDEX(('Списки блоков'!$N$2:$N986=B3)*(ROW('Списки блоков'!$N$2:$N986)<>ROW('Списки блоков'!$N$3)),0),0)),"","Сценаристы,") &IF(ISERROR(MATCH(1,INDEX(('Списки блоков'!$O$2:$O986=B3)*(ROW('Списки блоков'!$O$2:$O986)<>ROW('Списки блоков'!$O$3)),0),0)),"","Техники,") &IF(ISERROR(MATCH(1,INDEX(('Списки блоков'!$P$2:$P986=B3)*(ROW('Списки блоков'!$P$2:$P986)<>ROW('Списки блоков'!$P$3)),0),0)),"","УРС,") &IF(ISERROR(MATCH(1,INDEX(('Списки блоков'!$Q$2:$Q986=B3)*(ROW('Списки блоков'!$Q$2:$Q986)<>ROW('Списки блоков'!$Q$3)),0),0)),"","Фото,") &IF(ISERROR(MATCH(1,INDEX((#REF!=B3)*(ROW(#REF!)<>ROW(#REF!)),0),0)),"","ЭкоБлок,") &IF(ISERROR(MATCH(1,INDEX(('Списки блоков'!$R$2:$R986=B3)*(ROW('Списки блоков'!$R$2:$R986)<>ROW('Списки блоков'!$R$3)),0),0)),"","HR,") &IF(ISERROR(MATCH(1,INDEX(('Списки блоков'!$S$2:$S986=B3)*(ROW('Списки блоков'!$S$2:$S986)<>ROW('Списки блоков'!$S$3)),0),0)),"","Instagram,") &IF(ISERROR(MATCH(1,INDEX(('Списки блоков'!$T$2:$T986=B3)*(ROW('Списки блоков'!$T$2:$T986)<>ROW('Списки блоков'!$T$3)),0),0)),"","Zachёt,") &IF(ISERROR(MATCH(1,INDEX(('Списки блоков'!$U$2:$U986=B3)*(ROW('Списки блоков'!$U$2:$U986)<>ROW('Списки блоков'!$U$3)),0),0)),"","IT,") &IF(ISERROR(MATCH(1,INDEX(('Списки блоков'!$V$2:$V986=B3)*(ROW('Списки блоков'!$V$2:$V986)<>ROW('Списки блоков'!$V$3)),0),0)),"","ДК,")} -> Видеолаба,Декораторы,Дизайн,Склад,Сценаристы,УРС,Фото,HR,IT,ДК, | F3: 89163567797 | G3: https://vk.com/vrodealyona | H3: @megagnom111 | I3: alenushka2507@gmail.com | J3: Бюджет
A4: Алексеева Алена Игоревна | B4: Алексеева Алена(new) | C4: 215 | D4: Одинцово, Садовая 28а | E4: {=IF(ISERROR(MATCH(1,INDEX(('Списки блоков'!$B$2:$B986=B4)*(ROW('Списки блоков'!$B$2:$B986)<>ROW('Списки блоков'!$B$3)),0),0)),"","БДНС,") &IF(ISERROR(MATCH(1,INDEX(('Списки блоков'!$C$2:$C986=B4)*(ROW('Списки блоков'!$C$2:$C986)<>ROW('Списки блоков'!$C$3)),0),0)),"","Видеолаба,") &IF(ISERROR(MATCH(1,INDEX(('Списки блоков'!$D$2:$D986=B4)*(ROW('Списки блоков'!$D$2:$D986)<>ROW('Списки блоков'!$D$3)),0),0)),"","Декораторы,") &IF(ISERROR(MATCH(1,INDEX(('Списки блоков'!$E$2:$E986=B4)*(ROW('Списки блоков'!$E$2:$E986)<>ROW('Списки блоков'!$E$3)),0),0)),"","Дизайн,") &IF(ISERROR(MATCH(1,INDEX(('Списки блоков'!$F$2:$F986=B4)*(ROW('Списки блоков'!$F$2:$F986)<>ROW('Списки блоков'!$F$3)),0),0)),"","Досуг,") &IF(ISERROR(MATCH(1,INDEX(('Списки блоков'!$G$2:$G986=B4)*(ROW('Списки блоков'!$G$2:$G986)<>ROW('Списки блоков'!$G$3)),0),0)),"","Закупки,") &IF(ISERROR(MATCH(1,INDEX(('Списки блоков'!$H$2:$H986=B4)*(ROW('Списки блоков'!$H$2:$H986)<>ROW('Списки блоков'!$H$3)),0),0)),"","ИнфоБлок,") &IF(ISERROR(MATCH(1,INDEX(('Списки блоков'!$I$2:$I986=B4)*(ROW('Списки блоков'!$I$2:$I986)<>ROW('Списки блоков'!$I$3)),0),0)),"","КГ,") &IF(ISERROR(MATCH(1,INDEX(('Списки блоков'!$J$2:$J986=B4)*(ROW('Списки блоков'!$J$2:$J986)<>ROW('Списки блоков'!$J$3)),0),0)),"","МП,") &IF(ISERROR(MATCH(1,INDEX(('Списки блоков'!$K$2:$K986=B4)*(ROW('Списки блоков'!$K$2:$K986)<>ROW('Списки блоков'!$K$3)),0),0)),"","Профорги,") &IF(ISERROR(MATCH(1,INDEX(('Списки блоков'!$L$2:$L986=B4)*(ROW('Списки блоков'!$L$2:$L986)<>ROW('Списки блоков'!$L$3)),0),0)),"","Спонсоры,") &IF(ISERROR(MATCH(1,INDEX(('Списки блоков'!$M$2:$M986=B4)*(ROW('Списки блоков'!$M$2:$M986)<>ROW('Списки блоков'!$M$3)),0),0)),"","Склад,") &IF(ISERROR(MATCH(1,INDEX(('Списки блоков'!$N$2:$N986=B4)*(ROW('Списки блоков'!$N$2:$N986)<>ROW('Списки блоков'!$N$3)),0),0)),"","Сценаристы,") &IF(ISERROR(MATCH(1,INDEX(('Списки блоков'!$O$2:$O986=B4)*(ROW('Списки блоков'!$O$2:$O986)<>ROW('Списки блоков'!$O$3)),0),0)),"","Техники,") &IF(ISERROR(MATCH(1,INDEX(('Списки блоков'!$P$2:$P986=B4)*(ROW('Списки блоков'!$P$2:$P986)<>ROW('Списки блоков'!$P$3)),0),0)),"","УРС,") &IF(ISERROR(MATCH(1,INDEX(('Списки блоков'!$Q$2:$Q986=B4)*(ROW('Списки блоков'!$Q$2:$Q986)<>ROW('Списки блоков'!$Q$3)),0),0)),"","Фото,") &IF(ISERROR(MATCH(1,INDEX((#REF!=B4)*(ROW(#REF!)<>ROW(#REF!)),0),0)),"","ЭкоБлок,") &IF(ISERROR(MATCH(1,INDEX(('Списки блоков'!$R$2:$R986=B4)*(ROW('Списки блоков'!$R$2:$R986)<>ROW('Списки блоков'!$R$3)),0),0)),"","HR,") &IF(ISERROR(MATCH(1,INDEX(('Списки блоков'!$S$2:$S986=B4)*(ROW('Списки блоков'!$S$2:$S986)<>ROW('Списки блоков'!$S$3)),0),0)),"","Instagram,") &IF(ISERROR(MATCH(1,INDEX(('Списки блоков'!$T$2:$T986=B4)*(ROW('Списки блоков'!$T$2:$T986)<>ROW('Списки блоков'!$T$3)),0),0)),"","Zachёt,") &IF(ISERROR(MATCH(1,INDEX(('Списки блоков'!$U$2:$U986=B4)*(ROW('Списки блоков'!$U$2:$U986)<>ROW('Списки блоков'!$U$3)),0),0)),"","IT,") &IF(ISERROR(MATCH(1,INDEX(('Списки блоков'!$V$2:$V986=B4)*(ROW('Списки блоков'!$V$2:$V986)<>ROW('Списки блоков'!$V$3)),0),0)),"","ДК,")} -> МП, | F4: 89639224348 | G4: https://vk.com/olenenok1108 | H4: t.me/Alionka1108 | I4: alena.alekseeva.1108@gmail.com | J4: Бюджет
A5: Альтерман Лев Михайлович | B5: =LEFT(A5,FIND(CHAR(160),SUBSTITUTE(A5," ",CHAR(160),2)) - 1) -> Альтерман Лев | C5: 530 | D5: ЦСКА/Полежаевская | E5: {=IF(ISERROR(MATCH(1,INDEX(('Списки блоков'!$B$2:$B986=B5)*(ROW('Списки блоков'!$B$2:$B986)<>ROW('Списки блоков'!$B$3)),0),0)),"","БДНС,") &IF(ISERROR(MATCH(1,INDEX(('Списки блоков'!$C$2:$C986=B5)*(ROW('Списки блоков'!$C$2:$C986)<>ROW('Списки блоков'!$C$3)),0),0)),"","Видеолаба,") &IF(ISERROR(MATCH(1,INDEX(('Списки блоков'!$D$2:$D986=B5)*(ROW('Списки блоков'!$D$2:$D986)<>ROW('Списки блоков'!$D$3)),0),0)),"","Декораторы,") &IF(ISERROR(MATCH(1,INDEX(('Списки блоков'!$E$2:$E986=B5)*(ROW('Списки блоков'!$E$2:$E986)<>ROW('Списки блоков'!$E$3)),0),0)),"","Дизайн,") &IF(ISERROR(MATCH(1,INDEX(('Списки блоков'!$F$2:$F986=B5)*(ROW('Списки блоков'!$F$2:$F986)<>ROW('Списки блоков'!$F$3)),0),0)),"","Досуг,") &IF(ISERROR(MATCH(1,INDEX(('Списки блоков'!$G$2:$G986=B5)*(ROW('Списки блоков'!$G$2:$G986)<>ROW('Списки блоков'!$G$3)),0),0)),"","Закупки,") &IF(ISERROR(MATCH(1,INDEX(('Списки блоков'!$H$2:$H986=B5)*(ROW('Списки блоков'!$H$2:$H986)<>ROW('Списки блоков'!$H$3)),0),0)),"","ИнфоБлок,") &IF(ISERROR(MATCH(1,INDEX(('Списки блоков'!$I$2:$I986=B5)*(ROW('Списки блоков'!$I$2:$I986)<>ROW('Списки блоков'!$I$3)),0),0)),"","КГ,") &IF(ISERROR(MATCH(1,INDEX(('Списки блоков'!$J$2:$J986=B5)*(ROW('Списки блоков'!$J$2:$J986)<>ROW('Списки блоков'!$J$3)),0),0)),"","МП,") &IF(ISERROR(MATCH(1,INDEX(('Списки блоков'!$K$2:$K986=B5)*(ROW('Списки блоков'!$K$2:$K986)<>ROW('Списки блоков'!$K$3)),0),0)),"","Профорги,") &IF(ISERROR(MATCH(1,INDEX(('Списки блоков'!$L$2:$L986=B5)*(ROW('Списки блоков'!$L$2:$L986)<>ROW('Списки блоков'!$L$3)),0),0)),"","Спонсоры,") &IF(ISERROR(MATCH(1,INDEX(('Списки блоков'!$M$2:$M986=B5)*(ROW('Списки блоков'!$M$2:$M986)<>ROW('Списки блоков'!$M$3)),0),0)),"","Склад,") &IF(ISERROR(MATCH(1,INDEX(('Списки блоков'!$N$2:$N986=B5)*(ROW('Списки блоков'!$N$2:$N986)<>ROW('Списки блоков'!$N$3)),0),0)),"","Сценаристы,") &IF(ISERROR(MATCH(1,INDEX(('Списки блоков'!$O$2:$O986=B5)*(ROW('Списки блоков'!$O$2:$O986)<>ROW('Списки блоков'!$O$3)),0),0)),"","Техники,") &IF(ISERROR(MATCH(1,INDEX(('Списки блоков'!$P$2:$P986=B5)*(ROW('Списки блоков'!$P$2:$P986)<>ROW('Списки блоков'!$P$3)),0),0)),"","УРС,") &IF(ISERROR(MATCH(1,INDEX(('Списки блоков'!$Q$2:$Q986=B5)*(ROW('Списки блоков'!$Q$2:$Q986)<>ROW('Списки блоков'!$Q$3)),0),0)),"","Фото,") &IF(ISERROR(MATCH(1,INDEX((#REF!=B5)*(ROW(#REF!)<>ROW(#REF!)),0),0)),"","ЭкоБлок,") &IF(ISERROR(MATCH(1,INDEX(('Списки блоков'!$R$2:$R986=B5)*(ROW('Списки блоков'!$R$2:$R986)<>ROW('Списки блоков'!$R$3)),0),0)),"","HR,") &IF(ISERROR(MATCH(1,INDEX(('Списки блоков'!$S$2:$S986=B5)*(ROW('Списки блоков'!$S$2:$S986)<>ROW('Списки блоков'!$S$3)),0),0)),"","Instagram,") &IF(ISERROR(MATCH(1,INDEX(('Списки блоков'!$T$2:$T986=B5)*(ROW('Списки блоков'!$T$2:$T986)<>ROW('Списки блоков'!$T$3)),0),0)),"","Zachёt,") &IF(ISERROR(MATCH(1,INDEX(('Списки блоков'!$U$2:$U986=B5)*(ROW('Списки блоков'!$U$2:$U986)<>ROW('Списки блоков'!$U$3)),0),0)),"","IT,") &IF(ISERROR(MATCH(1,INDEX(('Списки блоков'!$V$2:$V986=B5)*(ROW('Списки блоков'!$V$2:$V986)<>ROW('Списки блоков'!$V$3)),0),0)),"","ДК,")} -> Закупки,Спонсоры,Фото,Instagram, | F5: 89163819339 | G5: https://vk.com/id246208831 | H5: https://t.me/lev_alterman | I5: leva.alm@gmail.com | J5: Бюджет
A6: Андреев Илья Андреевич | B6: =LEFT(A6,FIND(CHAR(160),SUBSTITUTE(A6," ",CHAR(160),2)) - 1) -> Андреев Илья | C6: 324 | D6: Одинцово, Говорова 50(станция Баковка) | E6: {=IF(ISERROR(MATCH(1,INDEX(('Списки блоков'!$B$2:$B986=B6)*(ROW('Списки блоков'!$B$2:$B986)<>ROW('Списки блоков'!$B$3)),0),0)),"","БДНС,") &IF(ISERROR(MATCH(1,INDEX(('Списки блоков'!$C$2:$C986=B6)*(ROW('Списки блоков'!$C$2:$C986)<>ROW('Списки блоков'!$C$3)),0),0)),"","Видеолаба,") &IF(ISERROR(MATCH(1,INDEX(('Списки блоков'!$D$2:$D986=B6)*(ROW('Списки блоков'!$D$2:$D986)<>ROW('Списки блоков'!$D$3)),0),0)),"","Декораторы,") &IF(ISERROR(MATCH(1,INDEX(('Списки блоков'!$E$2:$E986=B6)*(ROW('Списки блоков'!$E$2:$E986)<>ROW('Списки блоков'!$E$3)),0),0)),"","Дизайн,") &IF(ISERROR(MATCH(1,INDEX(('Списки блоков'!$F$2:$F986=B6)*(ROW('Списки блоков'!$F$2:$F986)<>ROW('Списки блоков'!$F$3)),0),0)),"","Досуг,") &IF(ISERROR(MATCH(1,INDEX(('Списки блоков'!$G$2:$G986=B6)*(ROW('Списки блоков'!$G$2:$G986)<>ROW('Списки блоков'!$G$3)),0),0)),"","Закупки,") &IF(ISERROR(MATCH(1,INDEX(('Списки блоков'!$H$2:$H986=B6)*(ROW('Списки блоков'!$H$2:$H986)<>ROW('Списки блоков'!$H$3)),0),0)),"","ИнфоБлок,") &IF(ISERROR(MATCH(1,INDEX(('Списки блоков'!$I$2:$I986=B6)*(ROW('Списки блоков'!$I$2:$I986)<>ROW('Списки блоков'!$I$3)),0),0)),"","КГ,") &IF(ISERROR(MATCH(1,INDEX(('Списки блоков'!$J$2:$J986=B6)*(ROW('Списки блоков'!$J$2:$J986)<>ROW('Списки блоков'!$J$3)),0),0)),"","МП,") &IF(ISERROR(MATCH(1,INDEX(('Списки блоков'!$K$2:$K986=B6)*(ROW('Списки блоков'!$K$2:$K986)<>ROW('Списки блоков'!$K$3)),0),0)),"","Профорги,") &IF(ISERROR(MATCH(1,INDEX(('Списки блоков'!$L$2:$L986=B6)*(ROW('Списки блоков'!$L$2:$L986)<>ROW('Списки блоков'!$L$3)),0),0)),"","Спонсоры,") &IF(ISERROR(MATCH(1,INDEX(('Списки блоков'!$M$2:$M986=B6)*(ROW('Списки блоков'!$M$2:$M986)<>ROW('Списки блоков'!$M$3)),0),0)),"","Склад,") &IF(ISERROR(MATCH(1,INDEX(('Списки блоков'!$N$2:$N986=B6)*(ROW('Списки блоков'!$N$2:$N986)<>ROW('Списки блоков'!$N$3)),0),0)),"","Сценаристы,") &IF(ISERROR(MATCH(1,INDEX(('Списки блоков'!$O$2:$O986=B6)*(ROW('Списки блоков'!$O$2:$O986)<>ROW('Списки блоков'!$O$3)),0),0)),"","Техники,") &IF(ISERROR(MATCH(1,INDEX(('Списки блоков'!$P$2:$P986=B6)*(ROW('Списки блоков'!$P$2:$P986)<>ROW('Списки блоков'!$P$3)),0),0)),"","УРС,") &IF(ISERROR(MATCH(1,INDEX(('Списки блоков'!$Q$2:$Q986=B6)*(ROW('Списки блоков'!$Q$2:$Q986)<>ROW('Списки блоков'!$Q$3)),0),0)),"","Фото,") &IF(ISERROR(MATCH(1,INDEX((#REF!=B6)*(ROW(#REF!)<>ROW(#REF!)),0),0)),"","ЭкоБлок,") &IF(ISERROR(MATCH(1,INDEX(('Списки блоков'!$R$2:$R986=B6)*(ROW('Списки блоков'!$R$2:$R986)<>ROW('Списки блоков'!$R$3)),0),0)),"","HR,") &IF(ISERROR(MATCH(1,INDEX(('Списки блоков'!$S$2:$S986=B6)*(ROW('Списки блоков'!$S$2:$S986)<>ROW('Списки блоков'!$S$3)),0),0)),"","Instagram,") &IF(ISERROR(MATCH(1,INDEX(('Списки блоков'!$T$2:$T986=B6)*(ROW('Списки блоков'!$T$2:$T986)<>ROW('Списки блоков'!$T$3)),0),0)),"","Zachёt,") &IF(ISERROR(MATCH(1,INDEX(('Списки блоков'!$U$2:$U986=B6)*(ROW('Списки блоков'!$U$2:$U986)<>ROW('Списки блоков'!$U$3)),0),0)),"","IT,") &IF(ISERROR(MATCH(1,INDEX(('Списки блоков'!$V$2:$V986=B6)*(ROW('Списки блоков'!$V$2:$V986)<>ROW('Списки блоков'!$V$3)),0),0)),"","ДК,")} -> Сценаристы,Фото, | F6: 89858741573 | G6: https://vk.com/id819691181 | H6: @Fantom_1324 | I6: Andreyevilia@gmail.com | J6: Контракт
A7: Андреева Елена Витальевна | B7: =LEFT(A7,FIND(CHAR(160),SUBSTITUTE(A7," ",CHAR(160),2)) - 1) -> Андреева Елена | C7: 424 | D7: Гз | E7: {=IF(ISERROR(MATCH(1,INDEX(('Списки блоков'!$B$2:$B986=B7)*(ROW('Списки блоков'!$B$2:$B986)<>ROW('Списки блоков'!$B$3)),0),0)),"","БДНС,") &IF(ISERROR(MATCH(1,INDEX(('Списки блоков'!$C$2:$C986=B7)*(ROW('Списки блоков'!$C$2:$C986)<>ROW('Списки блоков'!$C$3)),0),0)),"","Видеолаба,") &IF(ISERROR(MATCH(1,INDEX(('Списки блоков'!$D$2:$D986=B7)*(ROW('Списки блоков'!$D$2:$D986)<>ROW('Списки блоков'!$D$3)),0),0)),"","Декораторы,") &IF(ISERROR(MATCH(1,INDEX(('Списки блоков'!$E$2:$E986=B7)*(ROW('Списки блоков'!$E$2:$E986)<>ROW('Списки блоков'!$E$3)),0),0)),"","Дизайн,") &IF(ISERROR(MATCH(1,INDEX(('Списки блоков'!$F$2:$F986=B7)*(ROW('Списки блоков'!$F$2:$F986)<>ROW('Списки блоков'!$F$3)),0),0)),"","Досуг,") &IF(ISERROR(MATCH(1,INDEX(('Списки блоков'!$G$2:$G986=B7)*(ROW('Списки блоков'!$G$2:$G986)<>ROW('Списки блоков'!$G$3)),0),0)),"","Закупки,") &IF(ISERROR(MATCH(1,INDEX(('Списки блоков'!$H$2:$H986=B7)*(ROW('Списки блоков'!$H$2:$H986)<>ROW('Списки блоков'!$H$3)),0),0)),"","ИнфоБлок,") &IF(ISERROR(MATCH(1,INDEX(('Списки блоков'!$I$2:$I986=B7)*(ROW('Списки блоков'!$I$2:$I986)<>ROW('Списки блоков'!$I$3)),0),0)),"","КГ,") &IF(ISERROR(MATCH(1,INDEX(('Списки блоков'!$J$2:$J986=B7)*(ROW('Списки блоков'!$J$2:$J986)<>ROW('Списки блоков'!$J$3)),0),0)),"","МП,") &IF(ISERROR(MATCH(1,INDEX(('Списки блоков'!$K$2:$K986=B7)*(ROW('Списки блоков'!$K$2:$K986)<>ROW('Списки блоков'!$K$3)),0),0)),"","Профорги,") &IF(ISERROR(MATCH(1,INDEX(('Списки блоков'!$L$2:$L986=B7)*(ROW('Списки блоков'!$L$2:$L986)<>ROW('Списки блоков'!$L$3)),0),0)),"","Спонсоры,") &IF(ISERROR(MATCH(1,INDEX(('Списки блоков'!$M$2:$M986=B7)*(ROW('Списки блоков'!$M$2:$M986)<>ROW('Списки блоков'!$M$3)),0),0)),"","Склад,") &IF(ISERROR(MATCH(1,INDEX(('Списки блоков'!$N$2:$N986=B7)*(ROW('Списки блоков'!$N$2:$N986)<>ROW('Списки блоков'!$N$3)),0),0)),"","Сценаристы,") &IF(ISERROR(MATCH(1,INDEX(('Списки блоков'!$O$2:$O986=B7)*(ROW('Списки блоков'!$O$2:$O986)<>ROW('Списки блоков'!$O$3)),0),0)),"","Техники,") &IF(ISERROR(MATCH(1,INDEX(('Списки блоков'!$P$2:$P986=B7)*(ROW('Списки блоков'!$P$2:$P986)<>ROW('Списки блоков'!$P$3)),0),0)),"","УРС,") &IF(ISERROR(MATCH(1,INDEX(('Списки блоков'!$Q$2:$Q986=B7)*(ROW('Списки блоков'!$Q$2:$Q986)<>ROW('Списки блоков'!$Q$3)),0),0)),"","Фото,") &IF(ISERROR(MATCH(1,INDEX((#REF!=B7)*(ROW(#REF!)<>ROW(#REF!)),0),0)),"","ЭкоБлок,") &IF(ISERROR(MATCH(1,INDEX(('Списки блоков'!$R$2:$R986=B7)*(ROW('Списки блоков'!$R$2:$R986)<>ROW('Списки блоков'!$R$3)),0),0)),"","HR,") &IF(ISERROR(MATCH(1,INDEX(('Списки блоков'!$S$2:$S986=B7)*(ROW('Списки блоков'!$S$2:$S986)<>ROW('Списки блоков'!$S$3)),0),0)),"","Instagram,") &IF(ISERROR(MATCH(1,INDEX(('Списки блоков'!$T$2:$T986=B7)*(ROW('Списки блоков'!$T$2:$T986)<>ROW('Списки блоков'!$T$3)),0),0)),"","Zachёt,") &IF(ISERROR(MATCH(1,INDEX(('Списки блоков'!$U$2:$U986=B7)*(ROW('Списки блоков'!$U$2:$U986)<>ROW('Списки блоков'!$U$3)),0),0)),"","IT,") &IF(ISERROR(MATCH(1,INDEX(('Списки блоков'!$V$2:$V986=B7)*(ROW('Списки блоков'!$V$2:$V986)<>ROW('Списки блоков'!$V$3)),0),0)),"","ДК,")} -> Декораторы,УРС, | F7: 89872218408 | G7: https://vk.com/sch__in | H7: t.me/sch_in_in | I7: elenaand07062004@gmail.com | J7: Бюджет
A8: Андреков Егор Вадимович | B8: =LEFT(A8,FIND(CHAR(160),SUBSTITUTE(A8," ",CHAR(160),2)) - 1) -> Андреков Егор | C8: 212 | D8: Щелковская | E8: {=IF(ISERROR(MATCH(1,INDEX(('Списки блоков'!$B$2:$B986=B8)*(ROW('Списки блоков'!$B$2:$B986)<>ROW('Списки блоков'!$B$3)),0),0)),"","БДНС,") &IF(ISERROR(MATCH(1,INDEX(('Списки блоков'!$C$2:$C986=B8)*(ROW('Списки блоков'!$C$2:$C986)<>ROW('Списки блоков'!$C$3)),0),0)),"","Видеолаба,") &IF(ISERROR(MATCH(1,INDEX(('Списки блоков'!$D$2:$D986=B8)*(ROW('Списки блоков'!$D$2:$D986)<>ROW('Списки блоков'!$D$3)),0),0)),"","Декораторы,") &IF(ISERROR(MATCH(1,INDEX(('Списки блоков'!$E$2:$E986=B8)*(ROW('Списки блоков'!$E$2:$E986)<>ROW('Списки блоков'!$E$3)),0),0)),"","Дизайн,") &IF(ISERROR(MATCH(1,INDEX(('Списки блоков'!$F$2:$F986=B8)*(ROW('Списки блоков'!$F$2:$F986)<>ROW('Списки блоков'!$F$3)),0),0)),"","Досуг,") &IF(ISERROR(MATCH(1,INDEX(('Списки блоков'!$G$2:$G986=B8)*(ROW('Списки блоков'!$G$2:$G986)<>ROW('Списки блоков'!$G$3)),0),0)),"","Закупки,") &IF(ISERROR(MATCH(1,INDEX(('Списки блоков'!$H$2:$H986=B8)*(ROW('Списки блоков'!$H$2:$H986)<>ROW('Списки блоков'!$H$3)),0),0)),"","ИнфоБлок,") &IF(ISERROR(MATCH(1,INDEX(('Списки блоков'!$I$2:$I986=B8)*(ROW('Списки блоков'!$I$2:$I986)<>ROW('Списки блоков'!$I$3)),0),0)),"","КГ,") &IF(ISERROR(MATCH(1,INDEX(('Списки блоков'!$J$2:$J986=B8)*(ROW('Списки блоков'!$J$2:$J986)<>ROW('Списки блоков'!$J$3)),0),0)),"","МП,") &IF(ISERROR(MATCH(1,INDEX(('Списки блоков'!$K$2:$K986=B8)*(ROW('Списки блоков'!$K$2:$K986)<>ROW('Списки блоков'!$K$3)),0),0)),"","Профорги,") &IF(ISERROR(MATCH(1,INDEX(('Списки блоков'!$L$2:$L986=B8)*(ROW('Списки блоков'!$L$2:$L986)<>ROW('Списки блоков'!$L$3)),0),0)),"","Спонсоры,") &IF(ISERROR(MATCH(1,INDEX(('Списки блоков'!$M$2:$M986=B8)*(ROW('Списки блоков'!$M$2:$M986)<>ROW('Списки блоков'!$M$3)),0),0)),"","Склад,") &IF(ISERROR(MATCH(1,INDEX(('Списки блоков'!$N$2:$N986=B8)*(ROW('Списки блоков'!$N$2:$N986)<>ROW('Списки блоков'!$N$3)),0),0)),"","Сценаристы,") &IF(ISERROR(MATCH(1,INDEX(('Списки блоков'!$O$2:$O986=B8)*(ROW('Списки блоков'!$O$2:$O986)<>ROW('Списки блоков'!$O$3)),0),0)),"","Техники,") &IF(ISERROR(MATCH(1,INDEX(('Списки блоков'!$P$2:$P986=B8)*(ROW('Списки блоков'!$P$2:$P986)<>ROW('Списки блоков'!$P$3)),0),0)),"","УРС,") &IF(ISERROR(MATCH(1,INDEX(('Списки блоков'!$Q$2:$Q986=B8)*(ROW('Списки блоков'!$Q$2:$Q986)<>ROW('Списки блоков'!$Q$3)),0),0)),"","Фото,") &IF(ISERROR(MATCH(1,INDEX((#REF!=B8)*(ROW(#REF!)<>ROW(#REF!)),0),0)),"","ЭкоБлок,") &IF(ISERROR(MATCH(1,INDEX(('Списки блоков'!$R$2:$R986=B8)*(ROW('Списки блоков'!$R$2:$R986)<>ROW('Списки блоков'!$R$3)),0),0)),"","HR,") &IF(ISERROR(MATCH(1,INDEX(('Списки блоков'!$S$2:$S986=B8)*(ROW('Списки блоков'!$S$2:$S986)<>ROW('Списки блоков'!$S$3)),0),0)),"","Instagram,") &IF(ISERROR(MATCH(1,INDEX(('Списки блоков'!$T$2:$T986=B8)*(ROW('Списки блоков'!$T$2:$T986)<>ROW('Списки блоков'!$T$3)),0),0)),"","Zachёt,") &IF(ISERROR(MATCH(1,INDEX(('Списки блоков'!$U$2:$U986=B8)*(ROW('Списки блоков'!$U$2:$U986)<>ROW('Списки блоков'!$U$3)),0),0)),"","IT,") &IF(ISERROR(MATCH(1,INDEX(('Списки блоков'!$V$2:$V986=B8)*(ROW('Списки блоков'!$V$2:$V986)<>ROW('Списки блоков'!$V$3)),0),0)),"","ДК,")} -> Дизайн,Спонсоры,Сценаристы,Instagram, | F8: 89037684536 | G8: https://vk.com/id392290846 | H8: @e_andrekov | I8: e_andrekov@mail.ru | J8: Контракт
A9: Аристова Алла Алексеевна | B9: =LEFT(A9,FIND(CHAR(160),SUBSTITUTE(A9," ",CHAR(160),2)) - 1) -> Аристова Алла | C9: 102 | D9: ДСЛ | E9: {=IF(ISERROR(MATCH(1,INDEX(('Списки блоков'!$B$2:$B986=B9)*(ROW('Списки блоков'!$B$2:$B986)<>ROW('Списки блоков'!$B$3)),0),0)),"","БДНС,") &IF(ISERROR(MATCH(1,INDEX(('Списки блоков'!$C$2:$C986=B9)*(ROW('Списки блоков'!$C$2:$C986)<>ROW('Списки блоков'!$C$3)),0),0)),"","Видеолаба,") &IF(ISERROR(MATCH(1,INDEX(('Списки блоков'!$D$2:$D986=B9)*(ROW('Списки блоков'!$D$2:$D986)<>ROW('Списки блоков'!$D$3)),0),0)),"","Декораторы,") &IF(ISERROR(MATCH(1,INDEX(('Списки блоков'!$E$2:$E986=B9)*(ROW('Списки блоков'!$E$2:$E986)<>ROW('Списки блоков'!$E$3)),0),0)),"","Дизайн,") &IF(ISERROR(MATCH(1,INDEX(('Списки блоков'!$F$2:$F986=B9)*(ROW('Списки блоков'!$F$2:$F986)<>ROW('Списки блоков'!$F$3)),0),0)),"","Досуг,") &IF(ISERROR(MATCH(1,INDEX(('Списки блоков'!$G$2:$G986=B9)*(ROW('Списки блоков'!$G$2:$G986)<>ROW('Списки блоков'!$G$3)),0),0)),"","Закупки,") &IF(ISERROR(MATCH(1,INDEX(('Списки блоков'!$H$2:$H986=B9)*(ROW('Списки блоков'!$H$2:$H986)<>ROW('Списки блоков'!$H$3)),0),0)),"","ИнфоБлок,") &IF(ISERROR(MATCH(1,INDEX(('Списки блоков'!$I$2:$I986=B9)*(ROW('Списки блоков'!$I$2:$I986)<>ROW('Списки блоков'!$I$3)),0),0)),"","КГ,") &IF(ISERROR(MATCH(1,INDEX(('Списки блоков'!$J$2:$J986=B9)*(ROW('Списки блоков'!$J$2:$J986)<>ROW('Списки блоков'!$J$3)),0),0)),"","МП,") &IF(ISERROR(MATCH(1,INDEX(('Списки блоков'!$K$2:$K986=B9)*(ROW('Списки блоков'!$K$2:$K986)<>ROW('Списки блоков'!$K$3)),0),0)),"","Профорги,") &IF(ISERROR(MATCH(1,INDEX(('Списки блоков'!$L$2:$L986=B9)*(ROW('Списки блоков'!$L$2:$L986)<>ROW('Списки блоков'!$L$3)),0),0)),"","Спонсоры,") &IF(ISERROR(MATCH(1,INDEX(('Списки блоков'!$M$2:$M986=B9)*(ROW('Списки блоков'!$M$2:$M986)<>ROW('Списки блоков'!$M$3)),0),0)),"","Склад,") &IF(ISERROR(MATCH(1,INDEX(('Списки блоков'!$N$2:$N986=B9)*(ROW('Списки блоков'!$N$2:$N986)<>ROW('Списки блоков'!$N$3)),0),0)),"","Сценаристы,") &IF(ISERROR(MATCH(1,INDEX(('Списки блоков'!$O$2:$O986=B9)*(ROW('Списки блоков'!$O$2:$O986)<>ROW('Списки блоков'!$O$3)),0),0)),"","Техники,") &IF(ISERROR(MATCH(1,INDEX(('Списки блоков'!$P$2:$P986=B9)*(ROW('Списки блоков'!$P$2:$P986)<>ROW('Списки блоков'!$P$3)),0),0)),"","УРС,") &IF(ISERROR(MATCH(1,INDEX(('Списки блоков'!$Q$2:$Q986=B9)*(ROW('Списки блоков'!$Q$2:$Q986)<>ROW('Списки блоков'!$Q$3)),0),0)),"","Фото,") &IF(ISERROR(MATCH(1,INDEX((#REF!=B9)*(ROW(#REF!)<>ROW(#REF!)),0),0)),"","ЭкоБлок,") &IF(ISERROR(MATCH(1,INDEX(('Списки блоков'!$R$2:$R986=B9)*(ROW('Списки блоков'!$R$2:$R986)<>ROW('Списки блоков'!$R$3)),0),0)),"","HR,") &IF(ISERROR(MATCH(1,INDEX(('Списки блоков'!$S$2:$S986=B9)*(ROW('Списки блоков'!$S$2:$S986)<>ROW('Списки блоков'!$S$3)),0),0)),"","Instagram,") &IF(ISERROR(MATCH(1,INDEX(('Списки блоков'!$T$2:$T986=B9)*(ROW('Списки блоков'!$T$2:$T986)<>ROW('Списки блоков'!$T$3)),0),0)),"","Zachёt,") &IF(ISERROR(MATCH(1,INDEX(('Списки блоков'!$U$2:$U986=B9)*(ROW('Списки блоков'!$U$2:$U986)<>ROW('Списки блоков'!$U$3)),0),0)),"","IT,") &IF(ISERROR(MATCH(1,INDEX(('Списки блоков'!$V$2:$V986=B9)*(ROW('Списки блоков'!$V$2:$V986)<>ROW('Списки блоков'!$V$3)),0),0)),"","ДК,")} -> Декораторы,Профорги,IT, | F9: 89879444800 | G9: https://vk.com/allaristova | H9: https://t.me/allaristova | I9: alla.aristovaa@gmail.com | J9: Бюджет
A10: Балакин Денис Николаевич | B10: =LEFT(A10,FIND(CHAR(160),SUBSTITUTE(A10," ",CHAR(160),2)) - 1) -> Балакин Денис | C10: 210 | D10: Лермонтовский проспект | E10: {=IF(ISERROR(MATCH(1,INDEX(('Списки блоков'!$B$2:$B986=B10)*(ROW('Списки блоков'!$B$2:$B986)<>ROW('Списки блоков'!$B$3)),0),0)),"","БДНС,") &IF(ISERROR(MATCH(1,INDEX(('Списки блоков'!$C$2:$C986=B10)*(ROW('Списки блоков'!$C$2:$C986)<>ROW('Списки блоков'!$C$3)),0),0)),"","Видеолаба,") &IF(ISERROR(MATCH(1,INDEX(('Списки блоков'!$D$2:$D986=B10)*(ROW('Списки блоков'!$D$2:$D986)<>ROW('Списки блоков'!$D$3)),0),0)),"","Декораторы,") &IF(ISERROR(MATCH(1,INDEX(('Списки блоков'!$E$2:$E986=B10)*(ROW('Списки блоков'!$E$2:$E986)<>ROW('Списки блоков'!$E$3)),0),0)),"","Дизайн,") &IF(ISERROR(MATCH(1,INDEX(('Списки блоков'!$F$2:$F986=B10)*(ROW('Списки блоков'!$F$2:$F986)<>ROW('Списки блоков'!$F$3)),0),0)),"","Досуг,") &IF(ISERROR(MATCH(1,INDEX(('Списки блоков'!$G$2:$G986=B10)*(ROW('Списки блоков'!$G$2:$G986)<>ROW('Списки блоков'!$G$3)),0),0)),"","Закупки,") &IF(ISERROR(MATCH(1,INDEX(('Списки блоков'!$H$2:$H986=B10)*(ROW('Списки блоков'!$H$2:$H986)<>ROW('Списки блоков'!$H$3)),0),0)),"","ИнфоБлок,") &IF(ISERROR(MATCH(1,INDEX(('Списки блоков'!$I$2:$I986=B10)*(ROW('Списки блоков'!$I$2:$I986)<>ROW('Списки блоков'!$I$3)),0),0)),"","КГ,") &IF(ISERROR(MATCH(1,INDEX(('Списки блоков'!$J$2:$J986=B10)*(ROW('Списки блоков'!$J$2:$J986)<>ROW('Списки блоков'!$J$3)),0),0)),"","МП,") &IF(ISERROR(MATCH(1,INDEX(('Списки блоков'!$K$2:$K986=B10)*(ROW('Списки блоков'!$K$2:$K986)<>ROW('Списки блоков'!$K$3)),0),0)),"","Профорги,") &IF(ISERROR(MATCH(1,INDEX(('Списки блоков'!$L$2:$L986=B10)*(ROW('Списки блоков'!$L$2:$L986)<>ROW('Списки блоков'!$L$3)),0),0)),"","Спонсоры,") &IF(ISERROR(MATCH(1,INDEX(('Списки блоков'!$M$2:$M986=B10)*(ROW('Списки блоков'!$M$2:$M986)<>ROW('Списки блоков'!$M$3)),0),0)),"","Склад,") &IF(ISERROR(MATCH(1,INDEX(('Списки блоков'!$N$2:$N986=B10)*(ROW('Списки блоков'!$N$2:$N986)<>ROW('Списки блоков'!$N$3)),0),0)),"","Сценаристы,") &IF(ISERROR(MATCH(1,INDEX(('Списки блоков'!$O$2:$O986=B10)*(ROW('Списки блоков'!$O$2:$O986)<>ROW('Списки блоков'!$O$3)),0),0)),"","Техники,") &IF(ISERROR(MATCH(1,INDEX(('Списки блоков'!$P$2:$P986=B10)*(ROW('Списки блоков'!$P$2:$P986)<>ROW('Списки блоков'!$P$3)),0),0)),"","УРС,") &IF(ISERROR(MATCH(1,INDEX(('Списки блоков'!$Q$2:$Q986=B10)*(ROW('Списки блоков'!$Q$2:$Q986)<>ROW('Списки блоков'!$Q$3)),0),0)),"","Фото,") &IF(ISERROR(MATCH(1,INDEX((#REF!=B10)*(ROW(#REF!)<>ROW(#REF!)),0),0)),"","ЭкоБлок,") &IF(ISERROR(MATCH(1,INDEX(('Списки блоков'!$R$2:$R986=B10)*(ROW('Списки блоков'!$R$2:$R986)<>ROW('Списки блоков'!$R$3)),0),0)),"","HR,") &IF(ISERROR(MATCH(1,INDEX(('Списки блоков'!$S$2:$S986=B10)*(ROW('Списки блоков'!$S$2:$S986)<>ROW('Списки блоков'!$S$3)),0),0)),"","Instagram,") &IF(ISERROR(MATCH(1,INDEX(('Списки блоков'!$T$2:$T986=B10)*(ROW('Списки блоков'!$T$2:$T986)<>ROW('Списки блоков'!$T$3)),0),0)),"","Zachёt,") &IF(ISERROR(MATCH(1,INDEX(('Списки блоков'!$U$2:$U986=B10)*(ROW('Списки блоков'!$U$2:$U986)<>ROW('Списки блоков'!$U$3)),0),0)),"","IT,") &IF(ISERROR(MATCH(1,INDEX(('Списки блоков'!$V$2:$V986=B10)*(ROW('Списки блоков'!$V$2:$V986)<>ROW('Списки блоков'!$V$3)),0),0)),"","ДК,")} -> Видеолаба,Профорги,Instagram,IT, | F10: 89685119529 | G10: https://vk.com/govna_pocket | H10: @gavkoshmig | I10: Balakindenis3@gmail.com | J10: Бюджет
A11: Барсуков Егор Сергеевич | B11: =LEFT(A11,FIND(CHAR(160),SUBSTITUTE(A11," ",CHAR(160),2)) - 1) -> Барсуков Егор | C11: 141 | D11: ДСЛ | E11: {=IF(ISERROR(MATCH(1,INDEX(('Списки блоков'!$B$2:$B986=B11)*(ROW('Списки блоков'!$B$2:$B986)<>ROW('Списки блоков'!$B$3)),0),0)),"","БДНС,") &IF(ISERROR(MATCH(1,INDEX(('Списки блоков'!$C$2:$C986=B11)*(ROW('Списки блоков'!$C$2:$C986)<>ROW('Списки блоков'!$C$3)),0),0)),"","Видеолаба,") &IF(ISERROR(MATCH(1,INDEX(('Списки блоков'!$D$2:$D986=B11)*(ROW('Списки блоков'!$D$2:$D986)<>ROW('Списки блоков'!$D$3)),0),0)),"","Декораторы,") &IF(ISERROR(MATCH(1,INDEX(('Списки блоков'!$E$2:$E986=B11)*(ROW('Списки блоков'!$E$2:$E986)<>ROW('Списки блоков'!$E$3)),0),0)),"","Дизайн,") &IF(ISERROR(MATCH(1,INDEX(('Списки блоков'!$F$2:$F986=B11)*(ROW('Списки блоков'!$F$2:$F986)<>ROW('Списки блоков'!$F$3)),0),0)),"","Досуг,") &IF(ISERROR(MATCH(1,INDEX(('Списки блоков'!$G$2:$G986=B11)*(ROW('Списки блоков'!$G$2:$G986)<>ROW('Списки блоков'!$G$3)),0),0)),"","Закупки,") &IF(ISERROR(MATCH(1,INDEX(('Списки блоков'!$H$2:$H986=B11)*(ROW('Списки блоков'!$H$2:$H986)<>ROW('Списки блоков'!$H$3)),0),0)),"","ИнфоБлок,") &IF(ISERROR(MATCH(1,INDEX(('Списки блоков'!$I$2:$I986=B11)*(ROW('Списки блоков'!$I$2:$I986)<>ROW('Списки блоков'!$I$3)),0),0)),"","КГ,") &IF(ISERROR(MATCH(1,INDEX(('Списки блоков'!$J$2:$J986=B11)*(ROW('Списки блоков'!$J$2:$J986)<>ROW('Списки блоков'!$J$3)),0),0)),"","МП,") &IF(ISERROR(MATCH(1,INDEX(('Списки блоков'!$K$2:$K986=B11)*(ROW('Списки блоков'!$K$2:$K986)<>ROW('Списки блоков'!$K$3)),0),0)),"","Профорги,") &IF(ISERROR(MATCH(1,INDEX(('Списки блоков'!$L$2:$L986=B11)*(ROW('Списки блоков'!$L$2:$L986)<>ROW('Списки блоков'!$L$3)),0),0)),"","Спонсоры,") &IF(ISERROR(MATCH(1,INDEX(('Списки блоков'!$M$2:$M986=B11)*(ROW('Списки блоков'!$M$2:$M986)<>ROW('Списки блоков'!$M$3)),0),0)),"","Склад,") &IF(ISERROR(MATCH(1,INDEX(('Списки блоков'!$N$2:$N986=B11)*(ROW('Списки блоков'!$N$2:$N986)<>ROW('Списки блоков'!$N$3)),0),0)),"","Сценаристы,") &IF(ISERROR(MATCH(1,INDEX(('Списки блоков'!$O$2:$O986=B11)*(ROW('Списки блоков'!$O$2:$O986)<>ROW('Списки блоков'!$O$3)),0),0)),"","Техники,") &IF(ISERROR(MATCH(1,INDEX(('Списки блоков'!$P$2:$P986=B11)*(ROW('Списки блоков'!$P$2:$P986)<>ROW('Списки блоков'!$P$3)),0),0)),"","УРС,") &IF(ISERROR(MATCH(1,INDEX(('Списки блоков'!$Q$2:$Q986=B11)*(ROW('Списки блоков'!$Q$2:$Q986)<>ROW('Списки блоков'!$Q$3)),0),0)),"","Фото,") &IF(ISERROR(MATCH(1,INDEX((#REF!=B11)*(ROW(#REF!)<>ROW(#REF!)),0),0)),"","ЭкоБлок,") &IF(ISERROR(MATCH(1,INDEX(('Списки блоков'!$R$2:$R986=B11)*(ROW('Списки блоков'!$R$2:$R986)<>ROW('Списки блоков'!$R$3)),0),0)),"","HR,") &IF(ISERROR(MATCH(1,INDEX(('Списки блоков'!$S$2:$S986=B11)*(ROW('Списки блоков'!$S$2:$S986)<>ROW('Списки блоков'!$S$3)),0),0)),"","Instagram,") &IF(ISERROR(MATCH(1,INDEX(('Списки блоков'!$T$2:$T986=B11)*(ROW('Списки блоков'!$T$2:$T986)<>ROW('Списки блоков'!$T$3)),0),0)),"","Zachёt,") &IF(ISERROR(MATCH(1,INDEX(('Списки блоков'!$U$2:$U986=B11)*(ROW('Списки блоков'!$U$2:$U986)<>ROW('Списки блоков'!$U$3)),0),0)),"","IT,") &IF(ISERROR(MATCH(1,INDEX(('Списки блоков'!$V$2:$V986=B11)*(ROW('Списки блоков'!$V$2:$V986)<>ROW('Списки блоков'!$V$3)),0),0)),"","ДК,")} -> Видеолаба,Декораторы,Дизайн,Техники, | F11: +79528631032 | G11: https://vk.ru/id557684195 | H11: https://t.me/Finin1 | I11: not.a.fi141@gmail.com | J11: Бюджет
A12: Бедрин Павел Александрович | B12: =LEFT(A12,FIND(CHAR(160),SUBSTITUTE(A12," ",CHAR(160),2)) - 1) -> Бедрин Павел | C12: 628 | D12: Бибирево | E12: {=IF(ISERROR(MATCH(1,INDEX(('Списки блоков'!$B$2:$B986=B12)*(ROW('Списки блоков'!$B$2:$B986)<>ROW('Списки блоков'!$B$3)),0),0)),"","БДНС,") &IF(ISERROR(MATCH(1,INDEX(('Списки блоков'!$C$2:$C986=B12)*(ROW('Списки блоков'!$C$2:$C986)<>ROW('Списки блоков'!$C$3)),0),0)),"","Видеолаба,") &IF(ISERROR(MATCH(1,INDEX(('Списки блоков'!$D$2:$D986=B12)*(ROW('Списки блоков'!$D$2:$D986)<>ROW('Списки блоков'!$D$3)),0),0)),"","Декораторы,") &IF(ISERROR(MATCH(1,INDEX(('Списки блоков'!$E$2:$E986=B12)*(ROW('Списки блоков'!$E$2:$E986)<>ROW('Списки блоков'!$E$3)),0),0)),"","Дизайн,") &IF(ISERROR(MATCH(1,INDEX(('Списки блоков'!$F$2:$F986=B12)*(ROW('Списки блоков'!$F$2:$F986)<>ROW('Списки блоков'!$F$3)),0),0)),"","Досуг,") &IF(ISERROR(MATCH(1,INDEX(('Списки блоков'!$G$2:$G986=B12)*(ROW('Списки блоков'!$G$2:$G986)<>ROW('Списки блоков'!$G$3)),0),0)),"","Закупки,") &IF(ISERROR(MATCH(1,INDEX(('Списки блоков'!$H$2:$H986=B12)*(ROW('Списки блоков'!$H$2:$H986)<>ROW('Списки блоков'!$H$3)),0),0)),"","ИнфоБлок,") &IF(ISERROR(MATCH(1,INDEX(('Списки блоков'!$I$2:$I986=B12)*(ROW('Списки блоков'!$I$2:$I986)<>ROW('Списки блоков'!$I$3)),0),0)),"","КГ,") &IF(ISERROR(MATCH(1,INDEX(('Списки блоков'!$J$2:$J986=B12)*(ROW('Списки блоков'!$J$2:$J986)<>ROW('Списки блоков'!$J$3)),0),0)),"","МП,") &IF(ISERROR(MATCH(1,INDEX(('Списки блоков'!$K$2:$K986=B12)*(ROW('Списки блоков'!$K$2:$K986)<>ROW('Списки блоков'!$K$3)),0),0)),"","Профорги,") &IF(ISERROR(MATCH(1,INDEX(('Списки блоков'!$L$2:$L986=B12)*(ROW('Списки блоков'!$L$2:$L986)<>ROW('Списки блоков'!$L$3)),0),0)),"","Спонсоры,") &IF(ISERROR(MATCH(1,INDEX(('Списки блоков'!$M$2:$M986=B12)*(ROW('Списки блоков'!$M$2:$M986)<>ROW('Списки блоков'!$M$3)),0),0)),"","Склад,") &IF(ISERROR(MATCH(1,INDEX(('Списки блоков'!$N$2:$N986=B12)*(ROW('Списки блоков'!$N$2:$N986)<>ROW('Списки блоков'!$N$3)),0),0)),"","Сценаристы,") &IF(ISERROR(MATCH(1,INDEX(('Списки блоков'!$O$2:$O986=B12)*(ROW('Списки блоков'!$O$2:$O986)<>ROW('Списки блоков'!$O$3)),0),0)),"","Техники,") &IF(ISERROR(MATCH(1,INDEX(('Списки блоков'!$P$2:$P986=B12)*(ROW('Списки блоков'!$P$2:$P986)<>ROW('Списки блоков'!$P$3)),0),0)),"","УРС,") &IF(ISERROR(MATCH(1,INDEX(('Списки блоков'!$Q$2:$Q986=B12)*(ROW('Списки блоков'!$Q$2:$Q986)<>ROW('Списки блоков'!$Q$3)),0),0)),"","Фото,") &IF(ISERROR(MATCH(1,INDEX((#REF!=B12)*(ROW(#REF!)<>ROW(#REF!)),0),0)),"","ЭкоБлок,") &IF(ISERROR(MATCH(1,INDEX(('Списки блоков'!$R$2:$R986=B12)*(ROW('Списки блоков'!$R$2:$R986)<>ROW('Списки блоков'!$R$3)),0),0)),"","HR,") &IF(ISERROR(MATCH(1,INDEX(('Списки блоков'!$S$2:$S986=B12)*(ROW('Списки блоков'!$S$2:$S986)<>ROW('Списки блоков'!$S$3)),0),0)),"","Instagram,") &IF(ISERROR(MATCH(1,INDEX(('Списки блоков'!$T$2:$T986=B12)*(ROW('Списки блоков'!$T$2:$T986)<>ROW('Списки блоков'!$T$3)),0),0)),"","Zachёt,") &IF(ISERROR(MATCH(1,INDEX(('Списки блоков'!$U$2:$U986=B12)*(ROW('Списки блоков'!$U$2:$U986)<>ROW('Списки блоков'!$U$3)),0),0)),"","IT,") &IF(ISERROR(MATCH(1,INDEX(('Списки блоков'!$V$2:$V986=B12)*(ROW('Списки блоков'!$V$2:$V986)<>ROW('Списки блоков'!$V$3)),0),0)),"","ДК,")} -> Видеолаба,Дизайн, | F12: 89212999793 | G12: https://vk.com/pbedrin | H12: https://t.me/pbedrin | I12: s02240355@gse.cs.msu.ru | J12: Бюджет
A13: Беппиев Георгий Игоревич | B13: =LEFT(A13,FIND(CHAR(160),SUBSTITUTE(A13," ",CHAR(160),2)) - 1) -> Беппиев Георгий | C13: 312 | D13: Полежаевская/Хорошевская | E13: {=IF(ISERROR(MATCH(1,INDEX(('Списки блоков'!$B$2:$B986=B13)*(ROW('Списки блоков'!$B$2:$B986)<>ROW('Списки блоков'!$B$3)),0),0)),"","БДНС,") &IF(ISERROR(MATCH(1,INDEX(('Списки блоков'!$C$2:$C986=B13)*(ROW('Списки блоков'!$C$2:$C986)<>ROW('Списки блоков'!$C$3)),0),0)),"","Видеолаба,") &IF(ISERROR(MATCH(1,INDEX(('Списки блоков'!$D$2:$D986=B13)*(ROW('Списки блоков'!$D$2:$D986)<>ROW('Списки блоков'!$D$3)),0),0)),"","Декораторы,") &IF(ISERROR(MATCH(1,INDEX(('Списки блоков'!$E$2:$E986=B13)*(ROW('Списки блоков'!$E$2:$E986)<>ROW('Списки блоков'!$E$3)),0),0)),"","Дизайн,") &IF(ISERROR(MATCH(1,INDEX(('Списки блоков'!$F$2:$F986=B13)*(ROW('Списки блоков'!$F$2:$F986)<>ROW('Списки блоков'!$F$3)),0),0)),"","Досуг,") &IF(ISERROR(MATCH(1,INDEX(('Списки блоков'!$G$2:$G986=B13)*(ROW('Списки блоков'!$G$2:$G986)<>ROW('Списки блоков'!$G$3)),0),0)),"","Закупки,") &IF(ISERROR(MATCH(1,INDEX(('Списки блоков'!$H$2:$H986=B13)*(ROW('Списки блоков'!$H$2:$H986)<>ROW('Списки блоков'!$H$3)),0),0)),"","ИнфоБлок,") &IF(ISERROR(MATCH(1,INDEX(('Списки блоков'!$I$2:$I986=B13)*(ROW('Списки блоков'!$I$2:$I986)<>ROW('Списки блоков'!$I$3)),0),0)),"","КГ,") &IF(ISERROR(MATCH(1,INDEX(('Списки блоков'!$J$2:$J986=B13)*(ROW('Списки блоков'!$J$2:$J986)<>ROW('Списки блоков'!$J$3)),0),0)),"","МП,") &IF(ISERROR(MATCH(1,INDEX(('Списки блоков'!$K$2:$K986=B13)*(ROW('Списки блоков'!$K$2:$K986)<>ROW('Списки блоков'!$K$3)),0),0)),"","Профорги,") &IF(ISERROR(MATCH(1,INDEX(('Списки блоков'!$L$2:$L986=B13)*(ROW('Списки блоков'!$L$2:$L986)<>ROW('Списки блоков'!$L$3)),0),0)),"","Спонсоры,") &IF(ISERROR(MATCH(1,INDEX(('Списки блоков'!$M$2:$M986=B13)*(ROW('Списки блоков'!$M$2:$M986)<>ROW('Списки блоков'!$M$3)),0),0)),"","Склад,") &IF(ISERROR(MATCH(1,INDEX(('Списки блоков'!$N$2:$N986=B13)*(ROW('Списки блоков'!$N$2:$N986)<>ROW('Списки блоков'!$N$3)),0),0)),"","Сценаристы,") &IF(ISERROR(MATCH(1,INDEX(('Списки блоков'!$O$2:$O986=B13)*(ROW('Списки блоков'!$O$2:$O986)<>ROW('Списки блоков'!$O$3)),0),0)),"","Техники,") &IF(ISERROR(MATCH(1,INDEX(('Списки блоков'!$P$2:$P986=B13)*(ROW('Списки блоков'!$P$2:$P986)<>ROW('Списки блоков'!$P$3)),0),0)),"","УРС,") &IF(ISERROR(MATCH(1,INDEX(('Списки блоков'!$Q$2:$Q986=B13)*(ROW('Списки блоков'!$Q$2:$Q986)<>ROW('Списки блоков'!$Q$3)),0),0)),"","Фото,") &IF(ISERROR(MATCH(1,INDEX((#REF!=B13)*(ROW(#REF!)<>ROW(#REF!)),0),0)),"","ЭкоБлок,") &IF(ISERROR(MATCH(1,INDEX(('Списки блоков'!$R$2:$R986=B13)*(ROW('Списки блоков'!$R$2:$R986)<>ROW('Списки блоков'!$R$3)),0),0)),"","HR,") &IF(ISERROR(MATCH(1,INDEX(('Списки блоков'!$S$2:$S986=B13)*(ROW('Списки блоков'!$S$2:$S986)<>ROW('Списки блоков'!$S$3)),0),0)),"","Instagram,") &IF(ISERROR(MATCH(1,INDEX(('Списки блоков'!$T$2:$T986=B13)*(ROW('Списки блоков'!$T$2:$T986)<>ROW('Списки блоков'!$T$3)),0),0)),"","Zachёt,") &IF(ISERROR(MATCH(1,INDEX(('Списки блоков'!$U$2:$U986=B13)*(ROW('Списки блоков'!$U$2:$U986)<>ROW('Списки блоков'!$U$3)),0),0)),"","IT,") &IF(ISERROR(MATCH(1,INDEX(('Списки блоков'!$V$2:$V986=B13)*(ROW('Списки блоков'!$V$2:$V986)<>ROW('Списки блоков'!$V$3)),0),0)),"","ДК,")} | F13: 89260618663 | G13: https://vk.com/pmcvmk | H13: https://t.me/whatatimetobe_alive | I13: georgy.beppiev@gmail.com | J13: Бюджет
A14: Бодун Алена Александровна | B14: Бодун Алена | C14: 241 | D14: М Перово | E14: {=IF(ISERROR(MATCH(1,INDEX(('Списки блоков'!$B$2:$B986=B14)*(ROW('Списки блоков'!$B$2:$B986)<>ROW('Списки блоков'!$B$3)),0),0)),"","БДНС,") &IF(ISERROR(MATCH(1,INDEX(('Списки блоков'!$C$2:$C986=B14)*(ROW('Списки блоков'!$C$2:$C986)<>ROW('Списки блоков'!$C$3)),0),0)),"","Видеолаба,") &IF(ISERROR(MATCH(1,INDEX(('Списки блоков'!$D$2:$D986=B14)*(ROW('Списки блоков'!$D$2:$D986)<>ROW('Списки блоков'!$D$3)),0),0)),"","Декораторы,") &IF(ISERROR(MATCH(1,INDEX(('Списки блоков'!$E$2:$E986=B14)*(ROW('Списки блоков'!$E$2:$E986)<>ROW('Списки блоков'!$E$3)),0),0)),"","Дизайн,") &IF(ISERROR(MATCH(1,INDEX(('Списки блоков'!$F$2:$F986=B14)*(ROW('Списки блоков'!$F$2:$F986)<>ROW('Списки блоков'!$F$3)),0),0)),"","Досуг,") &IF(ISERROR(MATCH(1,INDEX(('Списки блоков'!$G$2:$G986=B14)*(ROW('Списки блоков'!$G$2:$G986)<>ROW('Списки блоков'!$G$3)),0),0)),"","Закупки,") &IF(ISERROR(MATCH(1,INDEX(('Списки блоков'!$H$2:$H986=B14)*(ROW('Списки блоков'!$H$2:$H986)<>ROW('Списки блоков'!$H$3)),0),0)),"","ИнфоБлок,") &IF(ISERROR(MATCH(1,INDEX(('Списки блоков'!$I$2:$I986=B14)*(ROW('Списки блоков'!$I$2:$I986)<>ROW('Списки блоков'!$I$3)),0),0)),"","КГ,") &IF(ISERROR(MATCH(1,INDEX(('Списки блоков'!$J$2:$J986=B14)*(ROW('Списки блоков'!$J$2:$J986)<>ROW('Списки блоков'!$J$3)),0),0)),"","МП,") &IF(ISERROR(MATCH(1,INDEX(('Списки блоков'!$K$2:$K986=B14)*(ROW('Списки блоков'!$K$2:$K986)<>ROW('Списки блоков'!$K$3)),0),0)),"","Профорги,") &IF(ISERROR(MATCH(1,INDEX(('Списки блоков'!$L$2:$L986=B14)*(ROW('Списки блоков'!$L$2:$L986)<>ROW('Списки блоков'!$L$3)),0),0)),"","Спонсоры,") &IF(ISERROR(MATCH(1,INDEX(('Списки блоков'!$M$2:$M986=B14)*(ROW('Списки блоков'!$M$2:$M986)<>ROW('Списки блоков'!$M$3)),0),0)),"","Склад,") &IF(ISERROR(MATCH(1,INDEX(('Списки блоков'!$N$2:$N986=B14)*(ROW('Списки блоков'!$N$2:$N986)<>ROW('Списки блоков'!$N$3)),0),0)),"","Сценаристы,") &IF(ISERROR(MATCH(1,INDEX(('Списки блоков'!$O$2:$O986=B14)*(ROW('Списки блоков'!$O$2:$O986)<>ROW('Списки блоков'!$O$3)),0),0)),"","Техники,") &IF(ISERROR(MATCH(1,INDEX(('Списки блоков'!$P$2:$P986=B14)*(ROW('Списки блоков'!$P$2:$P986)<>ROW('Списки блоков'!$P$3)),0),0)),"","УРС,") &IF(ISERROR(MATCH(1,INDEX(('Списки блоков'!$Q$2:$Q986=B14)*(ROW('Списки блоков'!$Q$2:$Q986)<>ROW('Списки блоков'!$Q$3)),0),0)),"","Фото,") &IF(ISERROR(MATCH(1,INDEX((#REF!=B14)*(ROW(#REF!)<>ROW(#REF!)),0),0)),"","ЭкоБлок,") &IF(ISERROR(MATCH(1,INDEX(('Списки блоков'!$R$2:$R986=B14)*(ROW('Списки блоков'!$R$2:$R986)<>ROW('Списки блоков'!$R$3)),0),0)),"","HR,") &IF(ISERROR(MATCH(1,INDEX(('Списки блоков'!$S$2:$S986=B14)*(ROW('Списки блоков'!$S$2:$S986)<>ROW('Списки блоков'!$S$3)),0),0)),"","Instagram,") &IF(ISERROR(MATCH(1,INDEX(('Списки блоков'!$T$2:$T986=B14)*(ROW('Списки блоков'!$T$2:$T986)<>ROW('Списки блоков'!$T$3)),0),0)),"","Zachёt,") &IF(ISERROR(MATCH(1,INDEX(('Списки блоков'!$U$2:$U986=B14)*(ROW('Списки блоков'!$U$2:$U986)<>ROW('Списки блоков'!$U$3)),0),0)),"","IT,") &IF(ISERROR(MATCH(1,INDEX(('Списки блоков'!$V$2:$V986=B14)*(ROW('Списки блоков'!$V$2:$V986)<>ROW('Списки блоков'!$V$3)),0),0)),"","ДК,")} -> УРС,Фото, | F14: 89057433029 | G14: https://vk.com/fafiuli | H14: @ulifafa | I14: alenab2312@gmail.com | J14: Бюджет
A15: Брылева София Алексеевна | B15: =LEFT(A15,FIND(CHAR(160),SUBSTITUTE(A15," ",CHAR(160),2)) - 1) -> Брылева София | C15: 109 | D15: Калужская | E15: {=IF(ISERROR(MATCH(1,INDEX(('Списки блоков'!$B$2:$B986=B15)*(ROW('Списки блоков'!$B$2:$B986)<>ROW('Списки блоков'!$B$3)),0),0)),"","БДНС,") &IF(ISERROR(MATCH(1,INDEX(('Списки блоков'!$C$2:$C986=B15)*(ROW('Списки блоков'!$C$2:$C986)<>ROW('Списки блоков'!$C$3)),0),0)),"","Видеолаба,") &IF(ISERROR(MATCH(1,INDEX(('Списки блоков'!$D$2:$D986=B15)*(ROW('Списки блоков'!$D$2:$D986)<>ROW('Списки блоков'!$D$3)),0),0)),"","Декораторы,") &IF(ISERROR(MATCH(1,INDEX(('Списки блоков'!$E$2:$E986=B15)*(ROW('Списки блоков'!$E$2:$E986)<>ROW('Списки блоков'!$E$3)),0),0)),"","Дизайн,") &IF(ISERROR(MATCH(1,INDEX(('Списки блоков'!$F$2:$F986=B15)*(ROW('Списки блоков'!$F$2:$F986)<>ROW('Списки блоков'!$F$3)),0),0)),"","Досуг,") &IF(ISERROR(MATCH(1,INDEX(('Списки блоков'!$G$2:$G986=B15)*(ROW('Списки блоков'!$G$2:$G986)<>ROW('Списки блоков'!$G$3)),0),0)),"","Закупки,") &IF(ISERROR(MATCH(1,INDEX(('Списки блоков'!$H$2:$H986=B15)*(ROW('Списки блоков'!$H$2:$H986)<>ROW('Списки блоков'!$H$3)),0),0)),"","ИнфоБлок,") &IF(ISERROR(MATCH(1,INDEX(('Списки блоков'!$I$2:$I986=B15)*(ROW('Списки блоков'!$I$2:$I986)<>ROW('Списки блоков'!$I$3)),0),0)),"","КГ,") &IF(ISERROR(MATCH(1,INDEX(('Списки блоков'!$J$2:$J986=B15)*(ROW('Списки блоков'!$J$2:$J986)<>ROW('Списки блоков'!$J$3)),0),0)),"","МП,") &IF(ISERROR(MATCH(1,INDEX(('Списки блоков'!$K$2:$K986=B15)*(ROW('Списки блоков'!$K$2:$K986)<>ROW('Списки блоков'!$K$3)),0),0)),"","Профорги,") &IF(ISERROR(MATCH(1,INDEX(('Списки блоков'!$L$2:$L986=B15)*(ROW('Списки блоков'!$L$2:$L986)<>ROW('Списки блоков'!$L$3)),0),0)),"","Спонсоры,") &IF(ISERROR(MATCH(1,INDEX(('Списки блоков'!$M$2:$M986=B15)*(ROW('Списки блоков'!$M$2:$M986)<>ROW('Списки блоков'!$M$3)),0),0)),"","Склад,") &IF(ISERROR(MATCH(1,INDEX(('Списки блоков'!$N$2:$N986=B15)*(ROW('Списки блоков'!$N$2:$N986)<>ROW('Списки блоков'!$N$3)),0),0)),"","Сценаристы,") &IF(ISERROR(MATCH(1,INDEX(('Списки блоков'!$O$2:$O986=B15)*(ROW('Списки блоков'!$O$2:$O986)<>ROW('Списки блоков'!$O$3)),0),0)),"","Техники,") &IF(ISERROR(MATCH(1,INDEX(('Списки блоков'!$P$2:$P986=B15)*(ROW('Списки блоков'!$P$2:$P986)<>ROW('Списки блоков'!$P$3)),0),0)),"","УРС,") &IF(ISERROR(MATCH(1,INDEX(('Списки блоков'!$Q$2:$Q986=B15)*(ROW('Списки блоков'!$Q$2:$Q986)<>ROW('Списки блоков'!$Q$3)),0),0)),"","Фото,") &IF(ISERROR(MATCH(1,INDEX((#REF!=B15)*(ROW(#REF!)<>ROW(#REF!)),0),0)),"","ЭкоБлок,") &IF(ISERROR(MATCH(1,INDEX(('Списки блоков'!$R$2:$R986=B15)*(ROW('Списки блоков'!$R$2:$R986)<>ROW('Списки блоков'!$R$3)),0),0)),"","HR,") &IF(ISERROR(MATCH(1,INDEX(('Списки блоков'!$S$2:$S986=B15)*(ROW('Списки блоков'!$S$2:$S986)<>ROW('Списки блоков'!$S$3)),0),0)),"","Instagram,") &IF(ISERROR(MATCH(1,INDEX(('Списки блоков'!$T$2:$T986=B15)*(ROW('Списки блоков'!$T$2:$T986)<>ROW('Списки блоков'!$T$3)),0),0)),"","Zachёt,") &IF(ISERROR(MATCH(1,INDEX(('Списки блоков'!$U$2:$U986=B15)*(ROW('Списки блоков'!$U$2:$U986)<>ROW('Списки блоков'!$U$3)),0),0)),"","IT,") &IF(ISERROR(MATCH(1,INDEX(('Списки блоков'!$V$2:$V986=B15)*(ROW('Списки блоков'!$V$2:$V986)<>ROW('Списки блоков'!$V$3)),0),0)),"","ДК,")} -> Техники, | F15: 89155237482 | G15: https://vk.ru/id349973300 | H15: t.me/bsofaa | I15: brylevasofia7@gmail.com | J15: Бюджет
A16: Булкин Антон Павлович | B16: =LEFT(A16,FIND(CHAR(160),SUBSTITUTE(A16," ",CHAR(160),2)) - 1) -> Булкин Антон | C16: 417 | D16: ДС Б1533п | E16: {=IF(ISERROR(MATCH(1,INDEX(('Списки блоков'!$B$2:$B986=B16)*(ROW('Списки блоков'!$B$2:$B986)<>ROW('Списки блоков'!$B$3)),0),0)),"","БДНС,") &IF(ISERROR(MATCH(1,INDEX(('Списки блоков'!$C$2:$C986=B16)*(ROW('Списки блоков'!$C$2:$C986)<>ROW('Списки блоков'!$C$3)),0),0)),"","Видеолаба,") &IF(ISERROR(MATCH(1,INDEX(('Списки блоков'!$D$2:$D986=B16)*(ROW('Списки блоков'!$D$2:$D986)<>ROW('Списки блоков'!$D$3)),0),0)),"","Декораторы,") &IF(ISERROR(MATCH(1,INDEX(('Списки блоков'!$E$2:$E986=B16)*(ROW('Списки блоков'!$E$2:$E986)<>ROW('Списки блоков'!$E$3)),0),0)),"","Дизайн,") &IF(ISERROR(MATCH(1,INDEX(('Списки блоков'!$F$2:$F986=B16)*(ROW('Списки блоков'!$F$2:$F986)<>ROW('Списки блоков'!$F$3)),0),0)),"","Досуг,") &IF(ISERROR(MATCH(1,INDEX(('Списки блоков'!$G$2:$G986=B16)*(ROW('Списки блоков'!$G$2:$G986)<>ROW('Списки блоков'!$G$3)),0),0)),"","Закупки,") &IF(ISERROR(MATCH(1,INDEX(('Списки блоков'!$H$2:$H986=B16)*(ROW('Списки блоков'!$H$2:$H986)<>ROW('Списки блоков'!$H$3)),0),0)),"","ИнфоБлок,") &IF(ISERROR(MATCH(1,INDEX(('Списки блоков'!$I$2:$I986=B16)*(ROW('Списки блоков'!$I$2:$I986)<>ROW('Списки блоков'!$I$3)),0),0)),"","КГ,") &IF(ISERROR(MATCH(1,INDEX(('Списки блоков'!$J$2:$J986=B16)*(ROW('Списки блоков'!$J$2:$J986)<>ROW('Списки блоков'!$J$3)),0),0)),"","МП,") &IF(ISERROR(MATCH(1,INDEX(('Списки блоков'!$K$2:$K986=B16)*(ROW('Списки блоков'!$K$2:$K986)<>ROW('Списки блоков'!$K$3)),0),0)),"","Профорги,") &IF(ISERROR(MATCH(1,INDEX(('Списки блоков'!$L$2:$L986=B16)*(ROW('Списки блоков'!$L$2:$L986)<>ROW('Списки блоков'!$L$3)),0),0)),"","Спонсоры,") &IF(ISERROR(MATCH(1,INDEX(('Списки блоков'!$M$2:$M986=B16)*(ROW('Списки блоков'!$M$2:$M986)<>ROW('Списки блоков'!$M$3)),0),0)),"","Склад,") &IF(ISERROR(MATCH(1,INDEX(('Списки блоков'!$N$2:$N986=B16)*(ROW('Списки блоков'!$N$2:$N986)<>ROW('Списки блоков'!$N$3)),0),0)),"","Сценаристы,") &IF(ISERROR(MATCH(1,INDEX(('Списки блоков'!$O$2:$O986=B16)*(ROW('Списки блоков'!$O$2:$O986)<>ROW('Списки блоков'!$O$3)),0),0)),"","Техники,") &IF(ISERROR(MATCH(1,INDEX(('Списки блоков'!$P$2:$P986=B16)*(ROW('Списки блоков'!$P$2:$P986)<>ROW('Списки блоков'!$P$3)),0),0)),"","УРС,") &IF(ISERROR(MATCH(1,INDEX(('Списки блоков'!$Q$2:$Q986=B16)*(ROW('Списки блоков'!$Q$2:$Q986)<>ROW('Списки блоков'!$Q$3)),0),0)),"","Фото,") &IF(ISERROR(MATCH(1,INDEX((#REF!=B16)*(ROW(#REF!)<>ROW(#REF!)),0),0)),"","ЭкоБлок,") &IF(ISERROR(MATCH(1,INDEX(('Списки блоков'!$R$2:$R986=B16)*(ROW('Списки блоков'!$R$2:$R986)<>ROW('Списки блоков'!$R$3)),0),0)),"","HR,") &IF(ISERROR(MATCH(1,INDEX(('Списки блоков'!$S$2:$S986=B16)*(ROW('Списки блоков'!$S$2:$S986)<>ROW('Списки блоков'!$S$3)),0),0)),"","Instagram,") &IF(ISERROR(MATCH(1,INDEX(('Списки блоков'!$T$2:$T986=B16)*(ROW('Списки блоков'!$T$2:$T986)<>ROW('Списки блоков'!$T$3)),0),0)),"","Zachёt,") &IF(ISERROR(MATCH(1,INDEX(('Списки блоков'!$U$2:$U986=B16)*(ROW('Списки блоков'!$U$2:$U986)<>ROW('Списки блоков'!$U$3)),0),0)),"","IT,") &IF(ISERROR(MATCH(1,INDEX(('Списки блоков'!$V$2:$V986=B16)*(ROW('Списки блоков'!$V$2:$V986)<>ROW('Списки блоков'!$V$3)),0),0)),"","ДК,")} -> Склад,HR,IT,ДК, | F16: 89645938620 | G16: https://vk.com/pochtichekhov | H16: @pochti_chekhov | I16: bulkin261@gmail.com | J16: Бюджет
A17: Валиев Радмир Рамильевич | B17: =LEFT(A17,FIND(CHAR(160),SUBSTITUTE(A17," ",CHAR(160),2)) - 1) -> Валиев Радмир | C17: 103 | D17: ДСЛ | E17: {=IF(ISERROR(MATCH(1,INDEX(('Списки блоков'!$B$2:$B986=B17)*(ROW('Списки блоков'!$B$2:$B986)<>ROW('Списки блоков'!$B$3)),0),0)),"","БДНС,") &IF(ISERROR(MATCH(1,INDEX(('Списки блоков'!$C$2:$C986=B17)*(ROW('Списки блоков'!$C$2:$C986)<>ROW('Списки блоков'!$C$3)),0),0)),"","Видеолаба,") &IF(ISERROR(MATCH(1,INDEX(('Списки блоков'!$D$2:$D986=B17)*(ROW('Списки блоков'!$D$2:$D986)<>ROW('Списки блоков'!$D$3)),0),0)),"","Декораторы,") &IF(ISERROR(MATCH(1,INDEX(('Списки блоков'!$E$2:$E986=B17)*(ROW('Списки блоков'!$E$2:$E986)<>ROW('Списки блоков'!$E$3)),0),0)),"","Дизайн,") &IF(ISERROR(MATCH(1,INDEX(('Списки блоков'!$F$2:$F986=B17)*(ROW('Списки блоков'!$F$2:$F986)<>ROW('Списки блоков'!$F$3)),0),0)),"","Досуг,") &IF(ISERROR(MATCH(1,INDEX(('Списки блоков'!$G$2:$G986=B17)*(ROW('Списки блоков'!$G$2:$G986)<>ROW('Списки блоков'!$G$3)),0),0)),"","Закупки,") &IF(ISERROR(MATCH(1,INDEX(('Списки блоков'!$H$2:$H986=B17)*(ROW('Списки блоков'!$H$2:$H986)<>ROW('Списки блоков'!$H$3)),0),0)),"","ИнфоБлок,") &IF(ISERROR(MATCH(1,INDEX(('Списки блоков'!$I$2:$I986=B17)*(ROW('Списки блоков'!$I$2:$I986)<>ROW('Списки блоков'!$I$3)),0),0)),"","КГ,") &IF(ISERROR(MATCH(1,INDEX(('Списки блоков'!$J$2:$J986=B17)*(ROW('Списки блоков'!$J$2:$J986)<>ROW('Списки блоков'!$J$3)),0),0)),"","МП,") &IF(ISERROR(MATCH(1,INDEX(('Списки блоков'!$K$2:$K986=B17)*(ROW('Списки блоков'!$K$2:$K986)<>ROW('Списки блоков'!$K$3)),0),0)),"","Профорги,") &IF(ISERROR(MATCH(1,INDEX(('Списки блоков'!$L$2:$L986=B17)*(ROW('Списки блоков'!$L$2:$L986)<>ROW('Списки блоков'!$L$3)),0),0)),"","Спонсоры,") &IF(ISERROR(MATCH(1,INDEX(('Списки блоков'!$M$2:$M986=B17)*(ROW('Списки блоков'!$M$2:$M986)<>ROW('Списки блоков'!$M$3)),0),0)),"","Склад,") &IF(ISERROR(MATCH(1,INDEX(('Списки блоков'!$N$2:$N986=B17)*(ROW('Списки блоков'!$N$2:$N986)<>ROW('Списки блоков'!$N$3)),0),0)),"","Сценаристы,") &IF(ISERROR(MATCH(1,INDEX(('Списки блоков'!$O$2:$O986=B17)*(ROW('Списки блоков'!$O$2:$O986)<>ROW('Списки блоков'!$O$3)),0),0)),"","Техники,") &IF(ISERROR(MATCH(1,INDEX(('Списки блоков'!$P$2:$P986=B17)*(ROW('Списки блоков'!$P$2:$P986)<>ROW('Списки блоков'!$P$3)),0),0)),"","УРС,") &IF(ISERROR(MATCH(1,INDEX(('Списки блоков'!$Q$2:$Q986=B17)*(ROW('Списки блоков'!$Q$2:$Q986)<>ROW('Списки блоков'!$Q$3)),0),0)),"","Фото,") &IF(ISERROR(MATCH(1,INDEX((#REF!=B17)*(ROW(#REF!)<>ROW(#REF!)),0),0)),"","ЭкоБлок,") &IF(ISERROR(MATCH(1,INDEX(('Списки блоков'!$R$2:$R986=B17)*(ROW('Списки блоков'!$R$2:$R986)<>ROW('Списки блоков'!$R$3)),0),0)),"","HR,") &IF(ISERROR(MATCH(1,INDEX(('Списки блоков'!$S$2:$S986=B17)*(ROW('Списки блоков'!$S$2:$S986)<>ROW('Списки блоков'!$S$3)),0),0)),"","Instagram,") &IF(ISERROR(MATCH(1,INDEX(('Списки блоков'!$T$2:$T986=B17)*(ROW('Списки блоков'!$T$2:$T986)<>ROW('Списки блоков'!$T$3)),0),0)),"","Zachёt,") &IF(ISERROR(MATCH(1,INDEX(('Списки блоков'!$U$2:$U986=B17)*(ROW('Списки блоков'!$U$2:$U986)<>ROW('Списки блоков'!$U$3)),0),0)),"","IT,") &IF(ISERROR(MATCH(1,INDEX(('Списки блоков'!$V$2:$V986=B17)*(ROW('Списки блоков'!$V$2:$V986)<>ROW('Списки блоков'!$V$3)),0),0)),"","ДК,")} -> Декораторы, | F17: 89088892318 | G17: https://vk.com/joyoftheworld | H17: https://t.me/radmyaus | I17: vradmir2007@gmail.com | J17: Бюджет
A18: Веревкин Илья Александрович | B18: =LEFT(A18,FIND(CHAR(160),SUBSTITUTE(A18," ",CHAR(160),2)) - 1) -> Веревкин Илья | C18: 111 | D18: марьина роща | E18: {=IF(ISERROR(MATCH(1,INDEX(('Списки блоков'!$B$2:$B986=B18)*(ROW('Списки блоков'!$B$2:$B986)<>ROW('Списки блоков'!$B$3)),0),0)),"","БДНС,") &IF(ISERROR(MATCH(1,INDEX(('Списки блоков'!$C$2:$C986=B18)*(ROW('Списки блоков'!$C$2:$C986)<>ROW('Списки блоков'!$C$3)),0),0)),"","Видеолаба,") &IF(ISERROR(MATCH(1,INDEX(('Списки блоков'!$D$2:$D986=B18)*(ROW('Списки блоков'!$D$2:$D986)<>ROW('Списки блоков'!$D$3)),0),0)),"","Декораторы,") &IF(ISERROR(MATCH(1,INDEX(('Списки блоков'!$E$2:$E986=B18)*(ROW('Списки блоков'!$E$2:$E986)<>ROW('Списки блоков'!$E$3)),0),0)),"","Дизайн,") &IF(ISERROR(MATCH(1,INDEX(('Списки блоков'!$F$2:$F986=B18)*(ROW('Списки блоков'!$F$2:$F986)<>ROW('Списки блоков'!$F$3)),0),0)),"","Досуг,") &IF(ISERROR(MATCH(1,INDEX(('Списки блоков'!$G$2:$G986=B18)*(ROW('Списки блоков'!$G$2:$G986)<>ROW('Списки блоков'!$G$3)),0),0)),"","Закупки,") &IF(ISERROR(MATCH(1,INDEX(('Списки блоков'!$H$2:$H986=B18)*(ROW('Списки блоков'!$H$2:$H986)<>ROW('Списки блоков'!$H$3)),0),0)),"","ИнфоБлок,") &IF(ISERROR(MATCH(1,INDEX(('Списки блоков'!$I$2:$I986=B18)*(ROW('Списки блоков'!$I$2:$I986)<>ROW('Списки блоков'!$I$3)),0),0)),"","КГ,") &IF(ISERROR(MATCH(1,INDEX(('Списки блоков'!$J$2:$J986=B18)*(ROW('Списки блоков'!$J$2:$J986)<>ROW('Списки блоков'!$J$3)),0),0)),"","МП,") &IF(ISERROR(MATCH(1,INDEX(('Списки блоков'!$K$2:$K986=B18)*(ROW('Списки блоков'!$K$2:$K986)<>ROW('Списки блоков'!$K$3)),0),0)),"","Профорги,") &IF(ISERROR(MATCH(1,INDEX(('Списки блоков'!$L$2:$L986=B18)*(ROW('Списки блоков'!$L$2:$L986)<>ROW('Списки блоков'!$L$3)),0),0)),"","Спонсоры,") &IF(ISERROR(MATCH(1,INDEX(('Списки блоков'!$M$2:$M986=B18)*(ROW('Списки блоков'!$M$2:$M986)<>ROW('Списки блоков'!$M$3)),0),0)),"","Склад,") &IF(ISERROR(MATCH(1,INDEX(('Списки блоков'!$N$2:$N986=B18)*(ROW('Списки блоков'!$N$2:$N986)<>ROW('Списки блоков'!$N$3)),0),0)),"","Сценаристы,") &IF(ISERROR(MATCH(1,INDEX(('Списки блоков'!$O$2:$O986=B18)*(ROW('Списки блоков'!$O$2:$O986)<>ROW('Списки блоков'!$O$3)),0),0)),"","Техники,") &IF(ISERROR(MATCH(1,INDEX(('Списки блоков'!$P$2:$P986=B18)*(ROW('Списки блоков'!$P$2:$P986)<>ROW('Списки блоков'!$P$3)),0),0)),"","УРС,") &IF(ISERROR(MATCH(1,INDEX(('Списки блоков'!$Q$2:$Q986=B18)*(ROW('Списки блоков'!$Q$2:$Q986)<>ROW('Списки блоков'!$Q$3)),0),0)),"","Фото,") &IF(ISERROR(MATCH(1,INDEX((#REF!=B18)*(ROW(#REF!)<>ROW(#REF!)),0),0)),"","ЭкоБлок,") &IF(ISERROR(MATCH(1,INDEX(('Списки блоков'!$R$2:$R986=B18)*(ROW('Списки блоков'!$R$2:$R986)<>ROW('Списки блоков'!$R$3)),0),0)),"","HR,") &IF(ISERROR(MATCH(1,INDEX(('Списки блоков'!$S$2:$S986=B18)*(ROW('Списки блоков'!$S$2:$S986)<>ROW('Списки блоков'!$S$3)),0),0)),"","Instagram,") &IF(ISERROR(MATCH(1,INDEX(('Списки блоков'!$T$2:$T986=B18)*(ROW('Списки блоков'!$T$2:$T986)<>ROW('Списки блоков'!$T$3)),0),0)),"","Zachёt,") &IF(ISERROR(MATCH(1,INDEX(('Списки блоков'!$U$2:$U986=B18)*(ROW('Списки блоков'!$U$2:$U986)<>ROW('Списки блоков'!$U$3)),0),0)),"","IT,") &IF(ISERROR(MATCH(1,INDEX(('Списки блоков'!$V$2:$V986=B18)*(ROW('Списки блоков'!$V$2:$V986)<>ROW('Списки блоков'!$V$3)),0),0)),"","ДК,")} -> Спонсоры,Техники, | F18: 89835298840 | G18: https://vk.com/endrezza | H18: @zerenicca | I18: endrezza@mail.ru | J18: Бюджет
A19: Винокуров Кирилл Владимирович | B19: =LEFT(A19,FIND(CHAR(160),SUBSTITUTE(A19," ",CHAR(160),2)) - 1) -> Винокуров Кирилл | C19: 321 | D19: Бабушкинская | E19: {=IF(ISERROR(MATCH(1,INDEX(('Списки блоков'!$B$2:$B986=B19)*(ROW('Списки блоков'!$B$2:$B986)<>ROW('Списки блоков'!$B$3)),0),0)),"","БДНС,") &IF(ISERROR(MATCH(1,INDEX(('Списки блоков'!$C$2:$C986=B19)*(ROW('Списки блоков'!$C$2:$C986)<>ROW('Списки блоков'!$C$3)),0),0)),"","Видеолаба,") &IF(ISERROR(MATCH(1,INDEX(('Списки блоков'!$D$2:$D986=B19)*(ROW('Списки блоков'!$D$2:$D986)<>ROW('Списки блоков'!$D$3)),0),0)),"","Декораторы,") &IF(ISERROR(MATCH(1,INDEX(('Списки блоков'!$E$2:$E986=B19)*(ROW('Списки блоков'!$E$2:$E986)<>ROW('Списки блоков'!$E$3)),0),0)),"","Дизайн,") &IF(ISERROR(MATCH(1,INDEX(('Списки блоков'!$F$2:$F986=B19)*(ROW('Списки блоков'!$F$2:$F986)<>ROW('Списки блоков'!$F$3)),0),0)),"","Досуг,") &IF(ISERROR(MATCH(1,INDEX(('Списки блоков'!$G$2:$G986=B19)*(ROW('Списки блоков'!$G$2:$G986)<>ROW('Списки блоков'!$G$3)),0),0)),"","Закупки,") &IF(ISERROR(MATCH(1,INDEX(('Списки блоков'!$H$2:$H986=B19)*(ROW('Списки блоков'!$H$2:$H986)<>ROW('Списки блоков'!$H$3)),0),0)),"","ИнфоБлок,") &IF(ISERROR(MATCH(1,INDEX(('Списки блоков'!$I$2:$I986=B19)*(ROW('Списки блоков'!$I$2:$I986)<>ROW('Списки блоков'!$I$3)),0),0)),"","КГ,") &IF(ISERROR(MATCH(1,INDEX(('Списки блоков'!$J$2:$J986=B19)*(ROW('Списки блоков'!$J$2:$J986)<>ROW('Списки блоков'!$J$3)),0),0)),"","МП,") &IF(ISERROR(MATCH(1,INDEX(('Списки блоков'!$K$2:$K986=B19)*(ROW('Списки блоков'!$K$2:$K986)<>ROW('Списки блоков'!$K$3)),0),0)),"","Профорги,") &IF(ISERROR(MATCH(1,INDEX(('Списки блоков'!$L$2:$L986=B19)*(ROW('Списки блоков'!$L$2:$L986)<>ROW('Списки блоков'!$L$3)),0),0)),"","Спонсоры,") &IF(ISERROR(MATCH(1,INDEX(('Списки блоков'!$M$2:$M986=B19)*(ROW('Списки блоков'!$M$2:$M986)<>ROW('Списки блоков'!$M$3)),0),0)),"","Склад,") &IF(ISERROR(MATCH(1,INDEX(('Списки блоков'!$N$2:$N986=B19)*(ROW('Списки блоков'!$N$2:$N986)<>ROW('Списки блоков'!$N$3)),0),0)),"","Сценаристы,") &IF(ISERROR(MATCH(1,INDEX(('Списки блоков'!$O$2:$O986=B19)*(ROW('Списки блоков'!$O$2:$O986)<>ROW('Списки блоков'!$O$3)),0),0)),"","Техники,") &IF(ISERROR(MATCH(1,INDEX(('Списки блоков'!$P$2:$P986=B19)*(ROW('Списки блоков'!$P$2:$P986)<>ROW('Списки блоков'!$P$3)),0),0)),"","УРС,") &IF(ISERROR(MATCH(1,INDEX(('Списки блоков'!$Q$2:$Q986=B19)*(ROW('Списки блоков'!$Q$2:$Q986)<>ROW('Списки блоков'!$Q$3)),0),0)),"","Фото,") &IF(ISERROR(MATCH(1,INDEX((#REF!=B19)*(ROW(#REF!)<>ROW(#REF!)),0),0)),"","ЭкоБлок,") &IF(ISERROR(MATCH(1,INDEX(('Списки блоков'!$R$2:$R986=B19)*(ROW('Списки блоков'!$R$2:$R986)<>ROW('Списки блоков'!$R$3)),0),0)),"","HR,") &IF(ISERROR(MATCH(1,INDEX(('Списки блоков'!$S$2:$S986=B19)*(ROW('Списки блоков'!$S$2:$S986)<>ROW('Списки блоков'!$S$3)),0),0)),"","Instagram,") &IF(ISERROR(MATCH(1,INDEX(('Списки блоков'!$T$2:$T986=B19)*(ROW('Списки блоков'!$T$2:$T986)<>ROW('Списки блоков'!$T$3)),0),0)),"","Zachёt,") &IF(ISERROR(MATCH(1,INDEX(('Списки блоков'!$U$2:$U986=B19)*(ROW('Списки блоков'!$U$2:$U986)<>ROW('Списки блоков'!$U$3)),0),0)),"","IT,") &IF(ISERROR(MATCH(1,INDEX(('Списки блоков'!$V$2:$V986=B19)*(ROW('Списки блоков'!$V$2:$V986)<>ROW('Списки блоков'!$V$3)),0),0)),"","ДК,")} -> БДНС,Видеолаба,Декораторы,Дизайн,Склад,Сценаристы,Техники,HR,ДК, | F19: 89099902934 | G19: https://vk.com/winesm0ker | H19: @WineSm0ker | I19: kirikvin8490@gmail.com | J19: Бюджет
